/home/yec23006/.local/lib/python3.11/site-packages/torchvision/models/_utils.py:208: UserWarning: The parameter 'pretrained' is deprecated since 0.13 and may be removed in the future, please use 'weights' instead.
  warnings.warn(
/home/yec23006/.local/lib/python3.11/site-packages/torchvision/models/_utils.py:223: UserWarning: Arguments other than a weight enum or `None` for 'weights' are deprecated since 0.13 and may be removed in the future. The current behavior is equivalent to passing `weights=MobileNet_V2_Weights.IMAGENET1K_V1`. You can also use `weights=MobileNet_V2_Weights.DEFAULT` to get the most up-to-date weights.
  warnings.warn(msg)
/home/yec23006/.conda/envs/torch121/lib/python3.11/site-packages/pandas/core/arrays/masked.py:60: UserWarning: Pandas requires version '1.3.6' or newer of 'bottleneck' (version '1.3.5' currently installed).
  from pandas.core import (
Epoch [1/200], Loss: 1653.2668
Epoch [2/200], Loss: 479.7220
Epoch [3/200], Loss: 479.2134
Epoch [4/200], Loss: 479.0635
Epoch [5/200], Loss: 478.6761
Epoch [6/200], Loss: 478.6528
Epoch [7/200], Loss: 478.5427
Epoch [8/200], Loss: 478.3586
Epoch [9/200], Loss: 478.3779
Epoch [10/200], Loss: 478.3300
Epoch [11/200], Loss: 478.3342
Epoch [12/200], Loss: 478.2796
Epoch [13/200], Loss: 478.2580
Epoch [14/200], Loss: 478.1767
Epoch [15/200], Loss: 478.2727
Epoch [16/200], Loss: 478.1071
Epoch [17/200], Loss: 478.0242
Epoch [18/200], Loss: 478.0649
Epoch [19/200], Loss: 477.9861
Epoch [20/200], Loss: 477.9770
Epoch [21/200], Loss: 477.9254
Epoch [22/200], Loss: 477.9326
Epoch [23/200], Loss: 477.8761
Epoch [24/200], Loss: 477.8626
Epoch [25/200], Loss: 477.8527
Epoch [26/200], Loss: 477.7935
Epoch [27/200], Loss: 477.7517
Epoch [28/200], Loss: 477.8128
Epoch [29/200], Loss: 477.7768
Epoch [30/200], Loss: 477.7489
Epoch [31/200], Loss: 477.7278
Epoch [32/200], Loss: 477.6854
Epoch [33/200], Loss: 477.6460
Epoch [34/200], Loss: 477.6238
Epoch [35/200], Loss: 477.5878
Epoch [36/200], Loss: 477.6114
Epoch [37/200], Loss: 477.6167
Epoch [38/200], Loss: 477.5948
Epoch [39/200], Loss: 477.5483
Epoch [40/200], Loss: 477.5830
Epoch [41/200], Loss: 477.5655
Epoch [42/200], Loss: 477.5133
Epoch [43/200], Loss: 477.5497
Epoch [44/200], Loss: 477.4658
Epoch [45/200], Loss: 477.4881
Epoch [46/200], Loss: 477.4700
Epoch [47/200], Loss: 477.4899
Epoch [48/200], Loss: 477.4579
Epoch [49/200], Loss: 477.4315
Epoch [50/200], Loss: 477.4196
Epoch [51/200], Loss: 477.4273
Epoch [52/200], Loss: 477.4640
Epoch [53/200], Loss: 477.4208
Epoch [54/200], Loss: 477.4626
Epoch [55/200], Loss: 477.3789
Epoch [56/200], Loss: 477.3930
Epoch [57/200], Loss: 477.4015
Epoch [58/200], Loss: 477.4295
Epoch [59/200], Loss: 477.3934
Epoch [60/200], Loss: 477.3459
Epoch [61/200], Loss: 477.3371
Epoch [62/200], Loss: 477.3621
Epoch [63/200], Loss: 477.3501
Epoch [64/200], Loss: 477.2930
Epoch [65/200], Loss: 477.3131
Epoch [66/200], Loss: 477.3039
Epoch [67/200], Loss: 477.3059
Epoch [68/200], Loss: 477.3244
Epoch [69/200], Loss: 477.2783
Epoch [70/200], Loss: 477.2822
Epoch [71/200], Loss: 477.2963
Epoch [72/200], Loss: 477.2445
Epoch [73/200], Loss: 477.2177
Epoch [74/200], Loss: 477.2217
Epoch [75/200], Loss: 477.2354
Epoch [76/200], Loss: 477.2526
Traceback (most recent call last):
  File "/home/yec23006/.conda/envs/torch121/lib/python3.11/site-packages/PIL/ImageFile.py", line 515, in _save
    fh = fp.fileno()
         ^^^^^^^^^
AttributeError: '_idat' object has no attribute 'fileno'
During handling of the above exception, another exception occurred:
Traceback (most recent call last):
  File "/home/yec23006/projects/research/merfish/FasterRCNN/SSD.py", line 285, in <module>
    train_ssd(model, train_loader, num_epochs=num_epochs, learning_rate=learning_rate, device=device)
  File "/home/yec23006/projects/research/merfish/FasterRCNN/SSD.py", line 237, in train_ssd
    input_images.append(wandb.Image(images_np[i]))
                        ^^^^^^^^^^^^^^^^^^^^^^^^^
  File "/home/yec23006/.conda/envs/torch121/lib/python3.11/site-packages/wandb/sdk/data_types/image.py", line 179, in __init__
    self._initialize_from_data(data_or_path, mode, file_type)
  File "/home/yec23006/.conda/envs/torch121/lib/python3.11/site-packages/wandb/sdk/data_types/image.py", line 336, in _initialize_from_data
    self._image.save(tmp_path, transparency=None)
  File "/home/yec23006/.conda/envs/torch121/lib/python3.11/site-packages/PIL/Image.py", line 2413, in save
    save_handler(self, fp, filename)
  File "/home/yec23006/.conda/envs/torch121/lib/python3.11/site-packages/PIL/PngImagePlugin.py", line 1398, in _save
    ImageFile._save(im, _idat(fp, chunk), [("zip", (0, 0) + im.size, 0, rawmode)])
  File "/home/yec23006/.conda/envs/torch121/lib/python3.11/site-packages/PIL/ImageFile.py", line 519, in _save
    _encode_tile(im, fp, tile, bufsize, None, exc)
  File "/home/yec23006/.conda/envs/torch121/lib/python3.11/site-packages/PIL/ImageFile.py", line 538, in _encode_tile
    errcode, data = encoder.encode(bufsize)[1:]
                    ^^^^^^^^^^^^^^^^^^^^^^^
KeyboardInterrupt